<sdf version='1.7'>
  <world name='default'>
    <light name='sun' type='directional'>
      <cast_shadows>1</cast_shadows>
      <pose>0 0 10 0 -0 0</pose>
      <diffuse>0.8 0.8 0.8 1</diffuse>
      <specular>0.2 0.2 0.2 1</specular>
      <attenuation>
        <range>1000</range>
        <constant>0.9</constant>
        <linear>0.01</linear>
        <quadratic>0.001</quadratic>
      </attenuation>
      <direction>-0.5 0.1 -0.9</direction>
      <spot>
        <inner_angle>0</inner_angle>
        <outer_angle>0</outer_angle>
        <falloff>0</falloff>
      </spot>
    </light>
    <physics type='ode'>
      <max_step_size>0.001</max_step_size>
      <real_time_factor>1</real_time_factor>
      <real_time_update_rate>1000</real_time_update_rate>
    </physics>
    <scene>
      <ambient>0.4 0.4 0.4 1</ambient>
      <background>0.7 0.7 0.7 1</background>
      <shadows>1</shadows>
    </scene>
    <spherical_coordinates>
      <surface_model>EARTH_WGS84</surface_model>
      <latitude_deg>0</latitude_deg>
      <longitude_deg>0</longitude_deg>
      <elevation>0</elevation>
      <heading_deg>0</heading_deg>
    </spherical_coordinates>
    <gui fullscreen='0'>
      <camera name='user_camera'>
        <pose>10.9939 -13.5531 11.0735 0 0.643643 2.29619</pose>
        <view_controller>orbit</view_controller>
        <projection_type>perspective</projection_type>
      </camera>
    </gui>
    <model name='turtlebot3_lane'>
      <static>1</static>
      <link name='link'>
        <collision name='collision'>
          <geometry>
            <plane>
              <normal>0 0 1</normal>
              <size>500 500</size>
            </plane>
          </geometry>
          <surface>
            <friction>
              <ode>
                <mu>0.5</mu>
                <mu2>0.5</mu2>
              </ode>
              <torsional>
                <ode/>
              </torsional>
            </friction>
            <contact>
              <ode/>
            </contact>
            <bounce/>
          </surface>
          <max_contacts>10</max_contacts>
        </collision>
        <visual name='visual_0'>
          <pose>0 0 0 0 -0 0</pose>
          <cast_shadows>0</cast_shadows>
          <geometry>
            <plane>
              <normal>0 0 1</normal>
              <size>20 20</size>
            </plane>
          </geometry>
          <material>
            <script>
              <uri>model://turtlebot3_lane/materials/scripts</uri>
              <uri>model://turtlebot3_lane/materials/textures</uri>
              <name>path/kobuki</name>
            </script>
          </material>
        </visual>
        <self_collide>0</self_collide>
        <enable_wind>0</enable_wind>
        <kinematic>0</kinematic>
      </link>
    </model>
    <gravity>0 0 -9.8</gravity>
    <magnetic_field>6e-06 2.3e-05 -4.2e-05</magnetic_field>
    <atmosphere type='adiabatic'/>
    <wind/>
    <state world_name='default'>
      <sim_time>223 911000000</sim_time>
      <real_time>81 144091074</real_time>
      <wall_time>1678736795 118271122</wall_time>
      <iterations>80572</iterations>
      <model name='turtlebot3_burger'>
        <pose>0.000119 -1.5e-05 0.008097 0.001447 0.01107 2.4e-05</pose>
        <scale>1 1 1</scale>
        <link name='base_footprint'>
          <pose>0.000119 -1.5e-05 0.008097 0.001447 0.01107 2.4e-05</pose>
          <velocity>-1e-05 1.6e-05 -0.079601 0.001005 0.000425 -0</velocity>
          <acceleration>-0.001525 -3.5e-05 1.35413 5.5e-05 0.104873 -2.5e-05</acceleration>
          <wrench>-0.001525 -3.5e-05 1.35413 0 -0 0</wrench>
        </link>
        <link name='base_link'>
          <pose>0.000119 -1.5e-05 0.008097 0.001447 0.01107 2.4e-05</pose>
          <velocity>-1e-05 1.6e-05 -0.079602 0.001005 0.000425 -0</velocity>
          <acceleration>0.005842 -3.8e-05 1.35729 5.5e-05 0.104861 -4.2e-05</acceleration>
          <wrench>0.004824 -3.1e-05 1.12076 0 -0 0</wrench>
        </link>
        <link name='base_scan'>
          <pose>0.000119 -1.5e-05 0.008097 0.001447 0.01107 2.4e-05</pose>
          <velocity>-1e-05 1.7e-05 -0.079607 0.001006 0.000424 0</velocity>
          <acceleration>0.015289 -4.4e-05 1.35534 5.3e-05 0.104792 -2.5e-05</acceleration>
          <wrench>0.001743 -5e-06 0.154509 0 -0 0</wrench>
        </link>
        <link name='camera_link'>
          <pose>0.000119 -1.5e-05 0.008097 0.001447 0.01107 2.4e-05</pose>
          <velocity>-1e-05 1.6e-05 -0.079606 0.001005 0.000425 -0</velocity>
          <acceleration>-0.001572 -3.6e-05 1.35355 5.5e-05 0.104827 -2.5e-05</acceleration>
          <wrench>-0.001572 -3.6e-05 1.35355 0 -0 0</wrench>
        </link>
        <link name='camera_rgb_optical_frame'>
          <pose>0.077144 -0.000148 0.10025 0.001447 0.01107 2.4e-05</pose>
          <velocity>2.8e-05 -7.6e-05 -0.079641 0.001006 0.000422 0</velocity>
          <acceleration>0.017621 -5.1e-05 1.33707 5.4e-05 0.104467 -2.5e-05</acceleration>
          <wrench>0.000617 -2e-06 0.046797 0 -0 0</wrench>
        </link>
        <link name='caster_back_link'>
          <pose>-0.08092 -1.1e-05 0.004992 -1.72413 -0.177362 0.020531</pose>
          <velocity>-1.3e-05 2.4e-05 -0.078242 -0.004818 -0.002532 0</velocity>
          <acceleration>1.1e-05 -8.2e-05 1.53852 0.002915 0.001423 -0</acceleration>
          <wrench>0 -0 0.007693 0 -0 0</wrench>
        </link>
        <link name='imu_link'>
          <pose>0.000119 -1.5e-05 0.008097 0.001447 0.01107 2.4e-05</pose>
          <velocity>-1e-05 1.7e-05 -0.079609 0.001005 0.000424 -0</velocity>
          <acceleration>-0.001603 -3.6e-05 1.35312 5.5e-05 0.104806 -2.5e-05</acceleration>
          <wrench>-0.001603 -3.6e-05 1.35312 0 -0 0</wrench>
        </link>
        <link name='wheel_left_link'>
          <pose>0.000112 -1.5e-05 0.008097 0.001447 0.011386 2.4e-05</pose>
          <velocity>4e-06 -1e-05 -0.079609 0.000992 0.000424 0</velocity>
          <acceleration>0.00342 -1e-06 1.35287 3.5e-05 0.103648 4e-06</acceleration>
          <wrench>9.7e-05 -0 0.038555 0 -0 0</wrench>
        </link>
        <link name='wheel_right_link'>
          <pose>0.000111 -1.5e-05 0.008097 0.001447 0.011431 2.4e-05</pose>
          <velocity>4e-06 -1e-05 -0.079612 0.000992 0.000424 0</velocity>
          <acceleration>0.003419 -1e-06 1.35299 4.4e-05 0.103619 8e-06</acceleration>
          <wrench>9.7e-05 -0 0.038559 0 -0 0</wrench>
        </link>
      </model>
      <model name='turtlebot3_lane'>
        <pose>0 0 0 0 -0 0</pose>
        <scale>1 1 1</scale>
        <link name='link'>
          <pose>0 0 0 0 -0 0</pose>
          <velocity>0 0 0 0 -0 0</velocity>
          <acceleration>0 0 0 0 -0 0</acceleration>
          <wrench>0 0 0 0 -0 0</wrench>
        </link>
      </model>
      <light name='sun'>
        <pose>0 0 10 0 -0 0</pose>
      </light>
    </state>
    <model name='turtlebot3_burger'>
      <pose>0.060473 -0.028743 0 0 -0 0</pose>
      <link name='base_footprint'>
        <self_collide>0</self_collide>
        <inertial>
          <pose>0 0 0 0 -0 0</pose>
          <inertia>
            <ixx>1</ixx>
            <ixy>0</ixy>
            <ixz>0</ixz>
            <iyy>1</iyy>
            <iyz>0</iyz>
            <izz>1</izz>
          </inertia>
          <mass>1</mass>
        </inertial>
        <enable_wind>0</enable_wind>
        <kinematic>0</kinematic>
      </link>
      <link name='base_link'>
        <inertial>
          <pose>-0.032 0 0.07 0 -0 0</pose>
          <inertia>
            <ixx>0.723974</ixx>
            <ixy>4.6864e-10</ixy>
            <ixz>-1.09526e-08</ixz>
            <iyy>0.723974</iyy>
            <iyz>2.85826e-09</iyz>
            <izz>0.65305</izz>
          </inertia>
          <mass>0.825735</mass>
        </inertial>
        <collision name='base_collision'>
          <pose>-0.032 0 0.07 0 -0 0</pose>
          <geometry>
            <box>
              <size>0.14 0.14 0.14</size>
            </box>
          </geometry>
          <max_contacts>10</max_contacts>
          <surface>
            <contact>
              <ode/>
            </contact>
            <bounce/>
            <friction>
              <torsional>
                <ode/>
              </torsional>
              <ode/>
            </friction>
          </surface>
        </collision>
        <visual name='base_visual'>
          <pose>-0.032 0 0 0 -0 0</pose>
          <geometry>
            <mesh>
              <uri>model://turtlebot3_burger/meshes/burger_base.dae</uri>
              <scale>0.001 0.001 0.001</scale>
            </mesh>
          </geometry>
        </visual>
        <self_collide>0</self_collide>
        <enable_wind>0</enable_wind>
        <kinematic>0</kinematic>
      </link>
      <link name='imu_link'>
        <sensor name='tb3_imu' type='imu'>
          <always_on>1</always_on>
          <update_rate>200</update_rate>
          <imu>
            <angular_velocity>
              <x>
                <noise type='gaussian'>
                  <mean>0</mean>
                  <stddev>0.0002</stddev>
                </noise>
              </x>
              <y>
                <noise type='gaussian'>
                  <mean>0</mean>
                  <stddev>0.0002</stddev>
                </noise>
              </y>
              <z>
                <noise type='gaussian'>
                  <mean>0</mean>
                  <stddev>0.0002</stddev>
                </noise>
              </z>
            </angular_velocity>
            <linear_acceleration>
              <x>
                <noise type='gaussian'>
                  <mean>0</mean>
                  <stddev>0.017</stddev>
                </noise>
              </x>
              <y>
                <noise type='gaussian'>
                  <mean>0</mean>
                  <stddev>0.017</stddev>
                </noise>
              </y>
              <z>
                <noise type='gaussian'>
                  <mean>0</mean>
                  <stddev>0.017</stddev>
                </noise>
              </z>
            </linear_acceleration>
            <angular_velocity/>
            <linear_acceleration/>
          </imu>
          <plugin name='turtlebot3_imu' filename='libgazebo_ros_imu_sensor.so'>
            <ros>
              <remapping>~/out:=imu</remapping>
            </ros>
          </plugin>
        </sensor>
        <self_collide>0</self_collide>
        <inertial>
          <pose>0 0 0 0 -0 0</pose>
          <inertia>
            <ixx>1</ixx>
            <ixy>0</ixy>
            <ixz>0</ixz>
            <iyy>1</iyy>
            <iyz>0</iyz>
            <izz>1</izz>
          </inertia>
          <mass>1</mass>
        </inertial>
        <enable_wind>0</enable_wind>
        <kinematic>0</kinematic>
      </link>
      <link name='base_scan'>
        <inertial>
          <pose>-0.02 0 0.161 0 -0 0</pose>
          <inertia>
            <ixx>0.001</ixx>
            <ixy>0</ixy>
            <ixz>0</ixz>
            <iyy>0.001</iyy>
            <iyz>0</iyz>
            <izz>0.001</izz>
          </inertia>
          <mass>0.114</mass>
        </inertial>
        <collision name='lidar_sensor_collision'>
          <pose>-0.02 0 0.161 0 -0 0</pose>
          <geometry>
            <cylinder>
              <radius>0.0508</radius>
              <length>0.055</length>
            </cylinder>
          </geometry>
          <max_contacts>10</max_contacts>
          <surface>
            <contact>
              <ode/>
            </contact>
            <bounce/>
            <friction>
              <torsional>
                <ode/>
              </torsional>
              <ode/>
            </friction>
          </surface>
        </collision>
        <visual name='lidar_sensor_visual'>
          <pose>-0.032 0 0.171 0 -0 0</pose>
          <geometry>
            <mesh>
              <uri>model://turtlebot3_burger/meshes/lds.dae</uri>
              <scale>0.001 0.001 0.001</scale>
            </mesh>
          </geometry>
        </visual>
        <sensor name='hls_lfcd_lds' type='ray'>
          <always_on>1</always_on>
          <visualize>1</visualize>
          <pose>-0.032 0 0.171 0 -0 0</pose>
          <update_rate>5</update_rate>
          <ray>
            <scan>
              <horizontal>
                <samples>360</samples>
                <resolution>1</resolution>
                <min_angle>0</min_angle>
                <max_angle>6.28</max_angle>
              </horizontal>
              <vertical>
                <samples>1</samples>
                <min_angle>0</min_angle>
                <max_angle>0</max_angle>
              </vertical>
            </scan>
            <range>
              <min>0.12</min>
              <max>3.5</max>
              <resolution>0.015</resolution>
            </range>
            <noise>
              <type>gaussian</type>
              <mean>0</mean>
              <stddev>0.01</stddev>
            </noise>
          </ray>
          <plugin name='turtlebot3_laserscan' filename='libgazebo_ros_ray_sensor.so'>
            <ros>
              <remapping>~/out:=scan</remapping>
            </ros>
            <output_type>sensor_msgs/LaserScan</output_type>
            <frame_name>base_scan</frame_name>
          </plugin>
        </sensor>
        <self_collide>0</self_collide>
        <enable_wind>0</enable_wind>
        <kinematic>0</kinematic>
      </link>
      <link name='wheel_left_link'>
        <inertial>
          <pose>0 0.08 0.023 -1.57 0 0</pose>
          <inertia>
            <ixx>0.00181582</ixx>
            <ixy>-9.3392e-12</ixy>
            <ixz>1.04909e-11</ixz>
            <iyy>0.00329221</iyy>
            <iyz>5.75694e-11</iyz>
            <izz>0.00181582</izz>
          </inertia>
          <mass>0.0284989</mass>
        </inertial>
        <collision name='wheel_left_collision'>
          <pose>0 0.08 0.023 -1.57 0 0</pose>
          <geometry>
            <cylinder>
              <radius>0.033</radius>
              <length>0.018</length>
            </cylinder>
          </geometry>
          <surface>
            <friction>
              <ode>
                <mu>100000</mu>
                <mu2>100000</mu2>
                <fdir1>0 0 0</fdir1>
                <slip1>0</slip1>
                <slip2>0</slip2>
              </ode>
              <torsional>
                <ode/>
              </torsional>
            </friction>
            <contact>
              <ode>
                <soft_cfm>0</soft_cfm>
                <soft_erp>0.2</soft_erp>
                <kp>100000</kp>
                <kd>1</kd>
                <max_vel>0.01</max_vel>
                <min_depth>0.001</min_depth>
              </ode>
            </contact>
            <bounce/>
          </surface>
          <max_contacts>10</max_contacts>
        </collision>
        <visual name='wheel_left_visual'>
          <pose>0 0.08 0.023 0 -0 0</pose>
          <geometry>
            <mesh>
              <uri>model://turtlebot3_burger/meshes/tire.dae</uri>
              <scale>0.001 0.001 0.001</scale>
            </mesh>
          </geometry>
        </visual>
        <self_collide>0</self_collide>
        <enable_wind>0</enable_wind>
        <kinematic>0</kinematic>
      </link>
      <link name='wheel_right_link'>
        <inertial>
          <pose>0 -0.08 0.023 -1.57 0 0</pose>
          <inertia>
            <ixx>0.00181582</ixx>
            <ixy>-9.3392e-12</ixy>
            <ixz>1.04909e-11</ixz>
            <iyy>0.00329221</iyy>
            <iyz>5.75694e-11</iyz>
            <izz>0.00181582</izz>
          </inertia>
          <mass>0.0284989</mass>
        </inertial>
        <collision name='wheel_right_collision'>
          <pose>0 -0.08 0.023 -1.57 0 0</pose>
          <geometry>
            <cylinder>
              <radius>0.033</radius>
              <length>0.018</length>
            </cylinder>
          </geometry>
          <surface>
            <friction>
              <ode>
                <mu>100000</mu>
                <mu2>100000</mu2>
                <fdir1>0 0 0</fdir1>
                <slip1>0</slip1>
                <slip2>0</slip2>
              </ode>
              <torsional>
                <ode/>
              </torsional>
            </friction>
            <contact>
              <ode>
                <soft_cfm>0</soft_cfm>
                <soft_erp>0.2</soft_erp>
                <kp>100000</kp>
                <kd>1</kd>
                <max_vel>0.01</max_vel>
                <min_depth>0.001</min_depth>
              </ode>
            </contact>
            <bounce/>
          </surface>
          <max_contacts>10</max_contacts>
        </collision>
        <visual name='wheel_right_visual'>
          <pose>0 -0.08 0.023 0 -0 0</pose>
          <geometry>
            <mesh>
              <uri>model://turtlebot3_burger/meshes/tire.dae</uri>
              <scale>0.001 0.001 0.001</scale>
            </mesh>
          </geometry>
        </visual>
        <self_collide>0</self_collide>
        <enable_wind>0</enable_wind>
        <kinematic>0</kinematic>
      </link>
      <link name='caster_back_link'>
        <pose>-0.081 0 -0.004 -1.57 0 0</pose>
        <inertial>
          <mass>0.005</mass>
          <inertia>
            <ixx>0.001</ixx>
            <ixy>0</ixy>
            <ixz>0</ixz>
            <iyy>0.001</iyy>
            <iyz>0</iyz>
            <izz>0.001</izz>
          </inertia>
          <pose>0 0 0 0 -0 0</pose>
        </inertial>
        <collision name='collision'>
          <geometry>
            <sphere>
              <radius>0.005</radius>
            </sphere>
          </geometry>
          <surface>
            <contact>
              <ode>
                <soft_cfm>0</soft_cfm>
                <soft_erp>0.2</soft_erp>
                <kp>100000</kp>
                <kd>1</kd>
                <max_vel>0.01</max_vel>
                <min_depth>0.001</min_depth>
              </ode>
            </contact>
            <bounce/>
            <friction>
              <torsional>
                <ode/>
              </torsional>
              <ode/>
            </friction>
          </surface>
          <max_contacts>10</max_contacts>
        </collision>
        <self_collide>0</self_collide>
        <enable_wind>0</enable_wind>
        <kinematic>0</kinematic>
      </link>
      <link name='camera_link'>
        <self_collide>0</self_collide>
        <inertial>
          <pose>0 0 0 0 -0 0</pose>
          <inertia>
            <ixx>1</ixx>
            <ixy>0</ixy>
            <ixz>0</ixz>
            <iyy>1</iyy>
            <iyz>0</iyz>
            <izz>1</izz>
          </inertia>
          <mass>1</mass>
        </inertial>
        <enable_wind>0</enable_wind>
        <kinematic>0</kinematic>
      </link>
      <link name='camera_rgb_optical_frame'>
        <inertial>
          <pose>0.076 0 0.093 0 -0 0</pose>
          <inertia>
            <ixx>0.001</ixx>
            <ixy>0</ixy>
            <ixz>0</ixz>
            <iyy>0.001</iyy>
            <iyz>0</iyz>
            <izz>0.001</izz>
          </inertia>
          <mass>0.035</mass>
        </inertial>
        <pose>0.076 0 0.093 0 -0 0</pose>
        <sensor name='camera' type='camera'>
          <always_on>1</always_on>
          <visualize>1</visualize>
          <update_rate>30</update_rate>
          <camera name='picam'>
            <horizontal_fov>1.0856</horizontal_fov>
            <image>
              <width>640</width>
              <height>480</height>
              <format>R8G8B8</format>
            </image>
            <clip>
              <near>0.03</near>
              <far>100</far>
            </clip>
            <noise>
              <type>gaussian</type>
              <mean>0</mean>
              <stddev>0.007</stddev>
            </noise>
          </camera>
          <plugin name='camera_driver' filename='libgazebo_ros_camera.so'>
            <ros/>
          </plugin>
        </sensor>
        <self_collide>0</self_collide>
        <enable_wind>0</enable_wind>
        <kinematic>0</kinematic>
      </link>
      <joint name='base_joint' type='fixed'>
        <parent>base_footprint</parent>
        <child>base_link</child>
        <pose>0 0 0.01 0 -0 0</pose>
      </joint>
      <joint name='wheel_left_joint' type='revolute'>
        <parent>base_link</parent>
        <child>wheel_left_link</child>
        <pose>0 0.08 0.023 -1.57 0 0</pose>
        <axis>
          <xyz>0 0 1</xyz>
          <limit>
            <lower>-1e+16</lower>
            <upper>1e+16</upper>
          </limit>
          <dynamics>
            <spring_reference>0</spring_reference>
            <spring_stiffness>0</spring_stiffness>
          </dynamics>
        </axis>
      </joint>
      <joint name='wheel_right_joint' type='revolute'>
        <parent>base_link</parent>
        <child>wheel_right_link</child>
        <pose>0 -0.08 0.023 -1.57 0 0</pose>
        <axis>
          <xyz>0 0 1</xyz>
          <limit>
            <lower>-1e+16</lower>
            <upper>1e+16</upper>
          </limit>
          <dynamics>
            <spring_reference>0</spring_reference>
            <spring_stiffness>0</spring_stiffness>
          </dynamics>
        </axis>
      </joint>
      <joint name='caster_back_joint' type='ball'>
        <parent>base_link</parent>
        <child>caster_back_link</child>
      </joint>
      <joint name='imu_joint' type='fixed'>
        <parent>base_link</parent>
        <child>imu_link</child>
        <pose>-0.032 0 0.068 0 -0 0</pose>
        <axis>
          <xyz>0 0 1</xyz>
          <limit>
            <lower>-1e+16</lower>
            <upper>1e+16</upper>
          </limit>
        </axis>
      </joint>
      <joint name='lidar_joint' type='fixed'>
        <parent>base_link</parent>
        <child>base_scan</child>
        <pose>-0.032 0 0.171 0 -0 0</pose>
        <axis>
          <xyz>0 0 1</xyz>
          <limit>
            <lower>-1e+16</lower>
            <upper>1e+16</upper>
          </limit>
        </axis>
      </joint>
      <joint name='camera_joint' type='fixed'>
        <parent>base_link</parent>
        <child>camera_link</child>
        <pose>0.073 -0.011 0.084 0 -0 0</pose>
        <axis>
          <xyz>0 0 1</xyz>
          <limit>
            <lower>-1e+16</lower>
            <upper>1e+16</upper>
          </limit>
        </axis>
      </joint>
      <joint name='camera_rgb_joint' type='fixed'>
        <parent>camera_link</parent>
        <child>camera_rgb_optical_frame</child>
        <pose>0.003 0.011 0.009 0 -0 0</pose>
        <axis>
          <xyz>0 0 1</xyz>
          <limit>
            <lower>-1e+16</lower>
            <upper>1e+16</upper>
          </limit>
        </axis>
      </joint>
      <plugin name='turtlebot3_diff_drive' filename='libgazebo_ros_diff_drive.so'>
        <ros/>
        <update_rate>30</update_rate>
        <left_joint>wheel_left_joint</left_joint>
        <right_joint>wheel_right_joint</right_joint>
        <wheel_separation>0.160</wheel_separation>
        <wheel_diameter>0.066</wheel_diameter>
        <max_wheel_torque>20</max_wheel_torque>
        <max_wheel_acceleration>1.0</max_wheel_acceleration>
        <command_topic>cmd_vel</command_topic>
        <publish_odom>1</publish_odom>
        <publish_odom_tf>1</publish_odom_tf>
        <publish_wheel_tf>0</publish_wheel_tf>
        <odometry_topic>odom</odometry_topic>
        <odometry_frame>odom</odometry_frame>
        <robot_base_frame>base_footprint</robot_base_frame>
      </plugin>
      <plugin name='turtlebot3_joint_state' filename='libgazebo_ros_joint_state_publisher.so'>
        <ros>
          <remapping>~/out:=joint_states</remapping>
        </ros>
        <update_rate>30</update_rate>
        <joint_name>wheel_left_joint</joint_name>
        <joint_name>wheel_right_joint</joint_name>
      </plugin>
    </model>
  </world>
</sdf>
